2025-10-16 20:20:56,225 INFO    MainThread:2860987 [wandb_setup.py:_flush():81] Current SDK version is 0.21.2
2025-10-16 20:20:56,225 INFO    MainThread:2860987 [wandb_setup.py:_flush():81] Configure stats pid to 2860987
2025-10-16 20:20:56,225 INFO    MainThread:2860987 [wandb_setup.py:_flush():81] Loading settings from /home/wvirany/.config/wandb/settings
2025-10-16 20:20:56,225 INFO    MainThread:2860987 [wandb_setup.py:_flush():81] Loading settings from /scratch/wvirany/mfal/experiments/single_fidelity/wandb/settings
2025-10-16 20:20:56,225 INFO    MainThread:2860987 [wandb_setup.py:_flush():81] Loading settings from environment variables
2025-10-16 20:20:56,225 INFO    MainThread:2860987 [wandb_init.py:setup_run_log_directory():686] Logging user logs to /scratch/wvirany/mfal/experiments/single_fidelity/wandb/run-20251016_202056-d620rqfw/logs/debug.log
2025-10-16 20:20:56,225 INFO    MainThread:2860987 [wandb_init.py:setup_run_log_directory():687] Logging internal logs to /scratch/wvirany/mfal/experiments/single_fidelity/wandb/run-20251016_202056-d620rqfw/logs/debug-internal.log
2025-10-16 20:20:56,225 INFO    MainThread:2860987 [wandb_init.py:init():813] calling init triggers
2025-10-16 20:20:56,225 INFO    MainThread:2860987 [wandb_init.py:init():818] wandb.init called with sweep_config: {}
config: {'embedding': 'morgan_fp', 'score_type': 'docking', 'n_iterations': 10, 'seed': 42, 'output_dir': 'results/single_fidelity', 'device': 'auto', 'wandb_mode': 'online', '_wandb': {}}
2025-10-16 20:20:56,225 INFO    MainThread:2860987 [wandb_init.py:init():854] starting backend
2025-10-16 20:20:56,458 INFO    MainThread:2860987 [wandb_init.py:init():857] sending inform_init request
2025-10-16 20:20:56,470 INFO    MainThread:2860987 [wandb_init.py:init():865] backend started and connected
2025-10-16 20:20:56,472 INFO    MainThread:2860987 [wandb_init.py:init():936] updated telemetry
2025-10-16 20:20:56,494 INFO    MainThread:2860987 [wandb_init.py:init():960] communicating run to backend with 90.0 second timeout
2025-10-16 20:20:56,861 INFO    MainThread:2860987 [wandb_init.py:init():1011] starting run threads in backend
2025-10-16 20:20:57,028 INFO    MainThread:2860987 [wandb_run.py:_console_start():2494] atexit reg
2025-10-16 20:20:57,028 INFO    MainThread:2860987 [wandb_run.py:_redirect():2342] redirect: wrap_raw
2025-10-16 20:20:57,028 INFO    MainThread:2860987 [wandb_run.py:_redirect():2411] Wrapping output streams.
2025-10-16 20:20:57,028 INFO    MainThread:2860987 [wandb_run.py:_redirect():2434] Redirects installed.
2025-10-16 20:20:57,037 INFO    MainThread:2860987 [wandb_init.py:init():1057] run started, returning control to user process
2025-10-16 20:20:57,261 INFO    MainThread:2860987 [wandb_run.py:_config_callback():1380] config_cb None None {'n_molecules': 59356, 'top1_threshold': -11.286, 'n_top1_molecules': 5}
2025-10-16 20:21:04,102 INFO    wandb-AsyncioManager-main:2860987 [service_client.py:_forward_responses():84] Reached EOF.
2025-10-16 20:21:04,102 INFO    wandb-AsyncioManager-main:2860987 [mailbox.py:close():137] Closing mailbox, abandoning 1 handles.
2025-10-16 20:21:24,316 ERROR   wandb-AsyncioManager-main:2860987 [asyncio_manager.py:fn_wrap_exceptions():183] Uncaught exception in run_soon callback.
Traceback (most recent call last):
  File "/scratch/wvirany/mfal/mfal_env/lib/python3.11/site-packages/wandb/sdk/lib/asyncio_manager.py", line 181, in fn_wrap_exceptions
    await fn()
  File "/scratch/wvirany/mfal/mfal_env/lib/python3.11/site-packages/wandb/sdk/lib/service/service_client.py", line 65, in _send_server_request
    await self._writer.drain()
  File "/cvmfs/soft.computecanada.ca/easybuild/software/2023/x86-64-v3/Compiler/gcccore/python/3.11.5/lib/python3.11/asyncio/streams.py", line 378, in drain
    await self._protocol._drain_helper()
  File "/cvmfs/soft.computecanada.ca/easybuild/software/2023/x86-64-v3/Compiler/gcccore/python/3.11.5/lib/python3.11/asyncio/streams.py", line 167, in _drain_helper
    raise ConnectionResetError('Connection lost')
ConnectionResetError: Connection lost
2025-10-16 20:21:24,351 ERROR   wandb-AsyncioManager-main:2860987 [asyncio_manager.py:fn_wrap_exceptions():183] Uncaught exception in run_soon callback.
Traceback (most recent call last):
  File "/scratch/wvirany/mfal/mfal_env/lib/python3.11/site-packages/wandb/sdk/lib/asyncio_manager.py", line 181, in fn_wrap_exceptions
    await fn()
  File "/scratch/wvirany/mfal/mfal_env/lib/python3.11/site-packages/wandb/sdk/lib/service/service_client.py", line 65, in _send_server_request
    await self._writer.drain()
  File "/cvmfs/soft.computecanada.ca/easybuild/software/2023/x86-64-v3/Compiler/gcccore/python/3.11.5/lib/python3.11/asyncio/streams.py", line 378, in drain
    await self._protocol._drain_helper()
  File "/cvmfs/soft.computecanada.ca/easybuild/software/2023/x86-64-v3/Compiler/gcccore/python/3.11.5/lib/python3.11/asyncio/streams.py", line 167, in _drain_helper
    raise ConnectionResetError('Connection lost')
ConnectionResetError: Connection lost
2025-10-16 20:21:24,352 ERROR   wandb-AsyncioManager-main:2860987 [asyncio_manager.py:fn_wrap_exceptions():183] Uncaught exception in run_soon callback.
Traceback (most recent call last):
  File "/scratch/wvirany/mfal/mfal_env/lib/python3.11/site-packages/wandb/sdk/lib/asyncio_manager.py", line 181, in fn_wrap_exceptions
    await fn()
  File "/scratch/wvirany/mfal/mfal_env/lib/python3.11/site-packages/wandb/sdk/lib/service/service_client.py", line 65, in _send_server_request
    await self._writer.drain()
  File "/cvmfs/soft.computecanada.ca/easybuild/software/2023/x86-64-v3/Compiler/gcccore/python/3.11.5/lib/python3.11/asyncio/streams.py", line 378, in drain
    await self._protocol._drain_helper()
  File "/cvmfs/soft.computecanada.ca/easybuild/software/2023/x86-64-v3/Compiler/gcccore/python/3.11.5/lib/python3.11/asyncio/streams.py", line 167, in _drain_helper
    raise ConnectionResetError('Connection lost')
ConnectionResetError: Connection lost
2025-10-16 20:21:24,353 ERROR   wandb-AsyncioManager-main:2860987 [asyncio_manager.py:fn_wrap_exceptions():183] Uncaught exception in run_soon callback.
Traceback (most recent call last):
  File "/scratch/wvirany/mfal/mfal_env/lib/python3.11/site-packages/wandb/sdk/lib/asyncio_manager.py", line 181, in fn_wrap_exceptions
    await fn()
  File "/scratch/wvirany/mfal/mfal_env/lib/python3.11/site-packages/wandb/sdk/lib/service/service_client.py", line 65, in _send_server_request
    await self._writer.drain()
  File "/cvmfs/soft.computecanada.ca/easybuild/software/2023/x86-64-v3/Compiler/gcccore/python/3.11.5/lib/python3.11/asyncio/streams.py", line 378, in drain
    await self._protocol._drain_helper()
  File "/cvmfs/soft.computecanada.ca/easybuild/software/2023/x86-64-v3/Compiler/gcccore/python/3.11.5/lib/python3.11/asyncio/streams.py", line 167, in _drain_helper
    raise ConnectionResetError('Connection lost')
ConnectionResetError: Connection lost
2025-10-16 20:21:24,353 ERROR   wandb-AsyncioManager-main:2860987 [asyncio_manager.py:fn_wrap_exceptions():183] Uncaught exception in run_soon callback.
Traceback (most recent call last):
  File "/scratch/wvirany/mfal/mfal_env/lib/python3.11/site-packages/wandb/sdk/lib/asyncio_manager.py", line 181, in fn_wrap_exceptions
    await fn()
  File "/scratch/wvirany/mfal/mfal_env/lib/python3.11/site-packages/wandb/sdk/lib/service/service_client.py", line 65, in _send_server_request
    await self._writer.drain()
  File "/cvmfs/soft.computecanada.ca/easybuild/software/2023/x86-64-v3/Compiler/gcccore/python/3.11.5/lib/python3.11/asyncio/streams.py", line 378, in drain
    await self._protocol._drain_helper()
  File "/cvmfs/soft.computecanada.ca/easybuild/software/2023/x86-64-v3/Compiler/gcccore/python/3.11.5/lib/python3.11/asyncio/streams.py", line 167, in _drain_helper
    raise ConnectionResetError('Connection lost')
ConnectionResetError: Connection lost
2025-10-16 20:21:24,354 ERROR   wandb-AsyncioManager-main:2860987 [asyncio_manager.py:fn_wrap_exceptions():183] Uncaught exception in run_soon callback.
Traceback (most recent call last):
  File "/scratch/wvirany/mfal/mfal_env/lib/python3.11/site-packages/wandb/sdk/lib/asyncio_manager.py", line 181, in fn_wrap_exceptions
    await fn()
  File "/scratch/wvirany/mfal/mfal_env/lib/python3.11/site-packages/wandb/sdk/lib/service/service_client.py", line 65, in _send_server_request
    await self._writer.drain()
  File "/cvmfs/soft.computecanada.ca/easybuild/software/2023/x86-64-v3/Compiler/gcccore/python/3.11.5/lib/python3.11/asyncio/streams.py", line 378, in drain
    await self._protocol._drain_helper()
  File "/cvmfs/soft.computecanada.ca/easybuild/software/2023/x86-64-v3/Compiler/gcccore/python/3.11.5/lib/python3.11/asyncio/streams.py", line 167, in _drain_helper
    raise ConnectionResetError('Connection lost')
ConnectionResetError: Connection lost
